ERROR 2025-07-23 12:32:18 views 128983 130100058126016 Lease creation failed: Field name `number_of_rooms` is not valid for model `Property`.
Traceback (most recent call last):
  File "/home/tnqn/Documents/rentsafe_project/apps/leases/api/views.py", line 49, in create
    serializer.is_valid(raise_exception=True)
  File "/home/tnqn/Documents/rentsafe_project/env/lib/python3.12/site-packages/rest_framework/serializers.py", line 227, in is_valid
    self._validated_data = self.run_validation(self.initial_data)
                           ^^^^^^^^^^^^^^^^^^^^^^^^^^^^^^^^^^^^^^
  File "/home/tnqn/Documents/rentsafe_project/env/lib/python3.12/site-packages/rest_framework/serializers.py", line 426, in run_validation
    value = self.to_internal_value(data)
            ^^^^^^^^^^^^^^^^^^^^^^^^^^^^
  File "/home/tnqn/Documents/rentsafe_project/env/lib/python3.12/site-packages/rest_framework/serializers.py", line 483, in to_internal_value
    validated_value = field.run_validation(primitive_value)
                      ^^^^^^^^^^^^^^^^^^^^^^^^^^^^^^^^^^^^^
  File "/home/tnqn/Documents/rentsafe_project/env/lib/python3.12/site-packages/rest_framework/serializers.py", line 426, in run_validation
    value = self.to_internal_value(data)
            ^^^^^^^^^^^^^^^^^^^^^^^^^^^^
  File "/home/tnqn/Documents/rentsafe_project/env/lib/python3.12/site-packages/rest_framework/serializers.py", line 479, in to_internal_value
    for field in fields:
  File "/home/tnqn/Documents/rentsafe_project/env/lib/python3.12/site-packages/rest_framework/serializers.py", line 362, in _writable_fields
    for field in self.fields.values():
                 ^^^^^^^^^^^
  File "/home/tnqn/Documents/rentsafe_project/env/lib/python3.12/site-packages/django/utils/functional.py", line 57, in __get__
    res = instance.__dict__[self.name] = self.func(instance)
                                         ^^^^^^^^^^^^^^^^^^^
  File "/home/tnqn/Documents/rentsafe_project/env/lib/python3.12/site-packages/rest_framework/serializers.py", line 356, in fields
    for key, value in self.get_fields().items():
                      ^^^^^^^^^^^^^^^^^
  File "/home/tnqn/Documents/rentsafe_project/env/lib/python3.12/site-packages/rest_framework/serializers.py", line 1076, in get_fields
    field_class, field_kwargs = self.build_field(
                                ^^^^^^^^^^^^^^^^^
  File "/home/tnqn/Documents/rentsafe_project/env/lib/python3.12/site-packages/rest_framework/serializers.py", line 1222, in build_field
    return self.build_unknown_field(field_name, model_class)
           ^^^^^^^^^^^^^^^^^^^^^^^^^^^^^^^^^^^^^^^^^^^^^^^^^
  File "/home/tnqn/Documents/rentsafe_project/env/lib/python3.12/site-packages/rest_framework/serializers.py", line 1340, in build_unknown_field
    raise ImproperlyConfigured(
django.core.exceptions.ImproperlyConfigured: Field name `number_of_rooms` is not valid for model `Property`.
ERROR 2025-07-23 12:36:48 views 130950 139468016187072 Lease creation failed: Field name `unit_context` is not valid for model `Unit`.
Traceback (most recent call last):
  File "/home/tnqn/Documents/rentsafe_project/apps/leases/api/views.py", line 49, in create
    serializer.is_valid(raise_exception=True)
  File "/home/tnqn/Documents/rentsafe_project/env/lib/python3.12/site-packages/rest_framework/serializers.py", line 227, in is_valid
    self._validated_data = self.run_validation(self.initial_data)
                           ^^^^^^^^^^^^^^^^^^^^^^^^^^^^^^^^^^^^^^
  File "/home/tnqn/Documents/rentsafe_project/env/lib/python3.12/site-packages/rest_framework/serializers.py", line 426, in run_validation
    value = self.to_internal_value(data)
            ^^^^^^^^^^^^^^^^^^^^^^^^^^^^
  File "/home/tnqn/Documents/rentsafe_project/env/lib/python3.12/site-packages/rest_framework/serializers.py", line 483, in to_internal_value
    validated_value = field.run_validation(primitive_value)
                      ^^^^^^^^^^^^^^^^^^^^^^^^^^^^^^^^^^^^^
  File "/home/tnqn/Documents/rentsafe_project/env/lib/python3.12/site-packages/rest_framework/serializers.py", line 426, in run_validation
    value = self.to_internal_value(data)
            ^^^^^^^^^^^^^^^^^^^^^^^^^^^^
  File "/home/tnqn/Documents/rentsafe_project/env/lib/python3.12/site-packages/rest_framework/serializers.py", line 479, in to_internal_value
    for field in fields:
  File "/home/tnqn/Documents/rentsafe_project/env/lib/python3.12/site-packages/rest_framework/serializers.py", line 362, in _writable_fields
    for field in self.fields.values():
                 ^^^^^^^^^^^
  File "/home/tnqn/Documents/rentsafe_project/env/lib/python3.12/site-packages/django/utils/functional.py", line 57, in __get__
    res = instance.__dict__[self.name] = self.func(instance)
                                         ^^^^^^^^^^^^^^^^^^^
  File "/home/tnqn/Documents/rentsafe_project/env/lib/python3.12/site-packages/rest_framework/serializers.py", line 356, in fields
    for key, value in self.get_fields().items():
                      ^^^^^^^^^^^^^^^^^
  File "/home/tnqn/Documents/rentsafe_project/env/lib/python3.12/site-packages/rest_framework/serializers.py", line 1076, in get_fields
    field_class, field_kwargs = self.build_field(
                                ^^^^^^^^^^^^^^^^^
  File "/home/tnqn/Documents/rentsafe_project/env/lib/python3.12/site-packages/rest_framework/serializers.py", line 1222, in build_field
    return self.build_unknown_field(field_name, model_class)
           ^^^^^^^^^^^^^^^^^^^^^^^^^^^^^^^^^^^^^^^^^^^^^^^^^
  File "/home/tnqn/Documents/rentsafe_project/env/lib/python3.12/site-packages/rest_framework/serializers.py", line 1340, in build_unknown_field
    raise ImproperlyConfigured(
django.core.exceptions.ImproperlyConfigured: Field name `unit_context` is not valid for model `Unit`.
ERROR 2025-07-23 12:37:36 views 131454 133125427427008 Lease creation failed: {'landlord_data': {'non_field_errors': [ErrorDetail(string="Landlord validation failed: [ErrorDetail(string='Individual with ID 1 does not exist.', code='invalid')]", code='invalid')]}, 'tenants': [{'lease': [ErrorDetail(string='This field is required.', code='required')]}], 'charges': [{'lease': [ErrorDetail(string='This field is required.', code='required')]}]}
Traceback (most recent call last):
  File "/home/tnqn/Documents/rentsafe_project/apps/leases/api/views.py", line 49, in create
    serializer.is_valid(raise_exception=True)
  File "/home/tnqn/Documents/rentsafe_project/env/lib/python3.12/site-packages/rest_framework/serializers.py", line 235, in is_valid
    raise ValidationError(self.errors)
rest_framework.exceptions.ValidationError: {'landlord_data': {'non_field_errors': [ErrorDetail(string="Landlord validation failed: [ErrorDetail(string='Individual with ID 1 does not exist.', code='invalid')]", code='invalid')]}, 'tenants': [{'lease': [ErrorDetail(string='This field is required.', code='required')]}], 'charges': [{'lease': [ErrorDetail(string='This field is required.', code='required')]}]}
ERROR 2025-07-23 12:37:55 views 131454 133125427427008 Lease creation failed: {'landlord_data': {'non_field_errors': [ErrorDetail(string="Invalid landlord type. Must be 'individual' or 'company_branch'.", code='invalid')]}, 'tenants': [{'lease': [ErrorDetail(string='This field is required.', code='required')]}], 'charges': [{'lease': [ErrorDetail(string='This field is required.', code='required')]}]}
Traceback (most recent call last):
  File "/home/tnqn/Documents/rentsafe_project/apps/leases/api/views.py", line 49, in create
    serializer.is_valid(raise_exception=True)
  File "/home/tnqn/Documents/rentsafe_project/env/lib/python3.12/site-packages/rest_framework/serializers.py", line 235, in is_valid
    raise ValidationError(self.errors)
rest_framework.exceptions.ValidationError: {'landlord_data': {'non_field_errors': [ErrorDetail(string="Invalid landlord type. Must be 'individual' or 'company_branch'.", code='invalid')]}, 'tenants': [{'lease': [ErrorDetail(string='This field is required.', code='required')]}], 'charges': [{'lease': [ErrorDetail(string='This field is required.', code='required')]}]}
ERROR 2025-07-23 12:39:16 views 132175 126215852652224 Lease creation failed: {'tenants': [{'lease': [ErrorDetail(string='This field is required.', code='required')]}], 'charges': [{'lease': [ErrorDetail(string='This field is required.', code='required')]}]}
Traceback (most recent call last):
  File "/home/tnqn/Documents/rentsafe_project/apps/leases/api/views.py", line 49, in create
    serializer.is_valid(raise_exception=True)
  File "/home/tnqn/Documents/rentsafe_project/env/lib/python3.12/site-packages/rest_framework/serializers.py", line 235, in is_valid
    raise ValidationError(self.errors)
rest_framework.exceptions.ValidationError: {'tenants': [{'lease': [ErrorDetail(string='This field is required.', code='required')]}], 'charges': [{'lease': [ErrorDetail(string='This field is required.', code='required')]}]}
ERROR 2025-07-23 12:40:23 views 132697 138369364391616 Lease creation failed: {'tenants': [{'lease': [ErrorDetail(string='This field is required.', code='required')]}], 'charges': [{'lease': [ErrorDetail(string='This field is required.', code='required')]}]}
Traceback (most recent call last):
  File "/home/tnqn/Documents/rentsafe_project/apps/leases/api/views.py", line 49, in create
    serializer.is_valid(raise_exception=True)
  File "/home/tnqn/Documents/rentsafe_project/env/lib/python3.12/site-packages/rest_framework/serializers.py", line 235, in is_valid
    raise ValidationError(self.errors)
rest_framework.exceptions.ValidationError: {'tenants': [{'lease': [ErrorDetail(string='This field is required.', code='required')]}], 'charges': [{'lease': [ErrorDetail(string='This field is required.', code='required')]}]}
ERROR 2025-07-23 12:40:52 views 132697 138369364391616 Lease creation failed: {'tenants': [{'lease': [ErrorDetail(string='This field is required.', code='required')]}], 'charges': [{'lease': [ErrorDetail(string='This field is required.', code='required')]}]}
Traceback (most recent call last):
  File "/home/tnqn/Documents/rentsafe_project/apps/leases/api/views.py", line 49, in create
    serializer.is_valid(raise_exception=True)
  File "/home/tnqn/Documents/rentsafe_project/env/lib/python3.12/site-packages/rest_framework/serializers.py", line 235, in is_valid
    raise ValidationError(self.errors)
rest_framework.exceptions.ValidationError: {'tenants': [{'lease': [ErrorDetail(string='This field is required.', code='required')]}], 'charges': [{'lease': [ErrorDetail(string='This field is required.', code='required')]}]}
ERROR 2025-07-23 12:47:34 views 135254 136153863812800 Lease creation failed: Cannot assign "'US'": "Address.country" must be a "Country" instance.
Traceback (most recent call last):
  File "/home/tnqn/Documents/rentsafe_project/apps/leases/api/views.py", line 51, in create
    lease = serializer.save()
            ^^^^^^^^^^^^^^^^^
  File "/home/tnqn/Documents/rentsafe_project/env/lib/python3.12/site-packages/rest_framework/serializers.py", line 212, in save
    self.instance = self.create(validated_data)
                    ^^^^^^^^^^^^^^^^^^^^^^^^^^^
  File "/usr/lib/python3.12/contextlib.py", line 81, in inner
    return func(*args, **kwds)
           ^^^^^^^^^^^^^^^^^^^
  File "/home/tnqn/Documents/rentsafe_project/apps/leases/api/serializers.py", line 368, in create
    property = property_serializer.save()
               ^^^^^^^^^^^^^^^^^^^^^^^^^^
  File "/home/tnqn/Documents/rentsafe_project/env/lib/python3.12/site-packages/rest_framework/serializers.py", line 212, in save
    self.instance = self.create(validated_data)
                    ^^^^^^^^^^^^^^^^^^^^^^^^^^^
  File "/home/tnqn/Documents/rentsafe_project/apps/leases/api/serializers.py", line 293, in create
    Address.objects.create(
  File "/home/tnqn/Documents/rentsafe_project/env/lib/python3.12/site-packages/django/db/models/manager.py", line 87, in manager_method
    return getattr(self.get_queryset(), name)(*args, **kwargs)
           ^^^^^^^^^^^^^^^^^^^^^^^^^^^^^^^^^^^^^^^^^^^^^^^^^^^
  File "/home/tnqn/Documents/rentsafe_project/env/lib/python3.12/site-packages/django/db/models/query.py", line 656, in create
    obj = self.model(**kwargs)
          ^^^^^^^^^^^^^^^^^^^^
  File "/home/tnqn/Documents/rentsafe_project/env/lib/python3.12/site-packages/django/db/models/base.py", line 543, in __init__
    _setattr(self, field.name, rel_obj)
  File "/home/tnqn/Documents/rentsafe_project/env/lib/python3.12/site-packages/django/db/models/fields/related_descriptors.py", line 266, in __set__
    raise ValueError(
ValueError: Cannot assign "'US'": "Address.country" must be a "Country" instance.
ERROR 2025-07-23 12:48:34 views 135254 136153840744128 Lease creation failed: Cannot assign "1": "Address.country" must be a "Country" instance.
Traceback (most recent call last):
  File "/home/tnqn/Documents/rentsafe_project/apps/leases/api/views.py", line 51, in create
    lease = serializer.save()
            ^^^^^^^^^^^^^^^^^
  File "/home/tnqn/Documents/rentsafe_project/env/lib/python3.12/site-packages/rest_framework/serializers.py", line 212, in save
    self.instance = self.create(validated_data)
                    ^^^^^^^^^^^^^^^^^^^^^^^^^^^
  File "/usr/lib/python3.12/contextlib.py", line 81, in inner
    return func(*args, **kwds)
           ^^^^^^^^^^^^^^^^^^^
  File "/home/tnqn/Documents/rentsafe_project/apps/leases/api/serializers.py", line 368, in create
    property = property_serializer.save()
               ^^^^^^^^^^^^^^^^^^^^^^^^^^
  File "/home/tnqn/Documents/rentsafe_project/env/lib/python3.12/site-packages/rest_framework/serializers.py", line 212, in save
    self.instance = self.create(validated_data)
                    ^^^^^^^^^^^^^^^^^^^^^^^^^^^
  File "/home/tnqn/Documents/rentsafe_project/apps/leases/api/serializers.py", line 293, in create
    Address.objects.create(
  File "/home/tnqn/Documents/rentsafe_project/env/lib/python3.12/site-packages/django/db/models/manager.py", line 87, in manager_method
    return getattr(self.get_queryset(), name)(*args, **kwargs)
           ^^^^^^^^^^^^^^^^^^^^^^^^^^^^^^^^^^^^^^^^^^^^^^^^^^^
  File "/home/tnqn/Documents/rentsafe_project/env/lib/python3.12/site-packages/django/db/models/query.py", line 656, in create
    obj = self.model(**kwargs)
          ^^^^^^^^^^^^^^^^^^^^
  File "/home/tnqn/Documents/rentsafe_project/env/lib/python3.12/site-packages/django/db/models/base.py", line 543, in __init__
    _setattr(self, field.name, rel_obj)
  File "/home/tnqn/Documents/rentsafe_project/env/lib/python3.12/site-packages/django/db/models/fields/related_descriptors.py", line 266, in __set__
    raise ValueError(
ValueError: Cannot assign "1": "Address.country" must be a "Country" instance.
ERROR 2025-07-23 13:00:17 views 140547 125462370055872 Lease creation failed: [ErrorDetail(string="Address creation failed: Field 'id' expected a number but got 'US'.", code='invalid')]
Traceback (most recent call last):
  File "/home/tnqn/Documents/rentsafe_project/env/lib/python3.12/site-packages/django/db/models/fields/__init__.py", line 2053, in get_prep_value
    return int(value)
           ^^^^^^^^^^
ValueError: invalid literal for int() with base 10: 'US'

The above exception was the direct cause of the following exception:

Traceback (most recent call last):
  File "/home/tnqn/Documents/rentsafe_project/apps/leases/api/serializers.py", line 307, in create
    country = Country.objects.get(id=address_data['country'])
              ^^^^^^^^^^^^^^^^^^^^^^^^^^^^^^^^^^^^^^^^^^^^^^^
  File "/home/tnqn/Documents/rentsafe_project/env/lib/python3.12/site-packages/django/db/models/manager.py", line 87, in manager_method
    return getattr(self.get_queryset(), name)(*args, **kwargs)
           ^^^^^^^^^^^^^^^^^^^^^^^^^^^^^^^^^^^^^^^^^^^^^^^^^^^
  File "/home/tnqn/Documents/rentsafe_project/env/lib/python3.12/site-packages/django/db/models/query.py", line 623, in get
    clone = self._chain() if self.query.combinator else self.filter(*args, **kwargs)
                                                        ^^^^^^^^^^^^^^^^^^^^^^^^^^^^
  File "/home/tnqn/Documents/rentsafe_project/env/lib/python3.12/site-packages/django/db/models/query.py", line 1436, in filter
    return self._filter_or_exclude(False, args, kwargs)
           ^^^^^^^^^^^^^^^^^^^^^^^^^^^^^^^^^^^^^^^^^^^^
  File "/home/tnqn/Documents/rentsafe_project/env/lib/python3.12/site-packages/django/db/models/query.py", line 1454, in _filter_or_exclude
    clone._filter_or_exclude_inplace(negate, args, kwargs)
  File "/home/tnqn/Documents/rentsafe_project/env/lib/python3.12/site-packages/django/db/models/query.py", line 1461, in _filter_or_exclude_inplace
    self._query.add_q(Q(*args, **kwargs))
  File "/home/tnqn/Documents/rentsafe_project/env/lib/python3.12/site-packages/django/db/models/sql/query.py", line 1545, in add_q
    clause, _ = self._add_q(q_object, self.used_aliases)
                ^^^^^^^^^^^^^^^^^^^^^^^^^^^^^^^^^^^^^^^^
  File "/home/tnqn/Documents/rentsafe_project/env/lib/python3.12/site-packages/django/db/models/sql/query.py", line 1576, in _add_q
    child_clause, needed_inner = self.build_filter(
                                 ^^^^^^^^^^^^^^^^^^
  File "/home/tnqn/Documents/rentsafe_project/env/lib/python3.12/site-packages/django/db/models/sql/query.py", line 1491, in build_filter
    condition = self.build_lookup(lookups, col, value)
                ^^^^^^^^^^^^^^^^^^^^^^^^^^^^^^^^^^^^^^
  File "/home/tnqn/Documents/rentsafe_project/env/lib/python3.12/site-packages/django/db/models/sql/query.py", line 1318, in build_lookup
    lookup = lookup_class(lhs, rhs)
             ^^^^^^^^^^^^^^^^^^^^^^
  File "/home/tnqn/Documents/rentsafe_project/env/lib/python3.12/site-packages/django/db/models/lookups.py", line 27, in __init__
    self.rhs = self.get_prep_lookup()
               ^^^^^^^^^^^^^^^^^^^^^^
  File "/home/tnqn/Documents/rentsafe_project/env/lib/python3.12/site-packages/django/db/models/lookups.py", line 341, in get_prep_lookup
    return super().get_prep_lookup()
           ^^^^^^^^^^^^^^^^^^^^^^^^^
  File "/home/tnqn/Documents/rentsafe_project/env/lib/python3.12/site-packages/django/db/models/lookups.py", line 85, in get_prep_lookup
    return self.lhs.output_field.get_prep_value(self.rhs)
           ^^^^^^^^^^^^^^^^^^^^^^^^^^^^^^^^^^^^^^^^^^^^^^
  File "/home/tnqn/Documents/rentsafe_project/env/lib/python3.12/site-packages/django/db/models/fields/__init__.py", line 2055, in get_prep_value
    raise e.__class__(
ValueError: Field 'id' expected a number but got 'US'.

During handling of the above exception, another exception occurred:

Traceback (most recent call last):
  File "/home/tnqn/Documents/rentsafe_project/apps/leases/api/views.py", line 51, in create
    lease = serializer.save()
            ^^^^^^^^^^^^^^^^^
  File "/home/tnqn/Documents/rentsafe_project/env/lib/python3.12/site-packages/rest_framework/serializers.py", line 212, in save
    self.instance = self.create(validated_data)
                    ^^^^^^^^^^^^^^^^^^^^^^^^^^^
  File "/usr/lib/python3.12/contextlib.py", line 81, in inner
    return func(*args, **kwds)
           ^^^^^^^^^^^^^^^^^^^
  File "/home/tnqn/Documents/rentsafe_project/apps/leases/api/serializers.py", line 401, in create
    property = property_serializer.save()
               ^^^^^^^^^^^^^^^^^^^^^^^^^^
  File "/home/tnqn/Documents/rentsafe_project/env/lib/python3.12/site-packages/rest_framework/serializers.py", line 212, in save
    self.instance = self.create(validated_data)
                    ^^^^^^^^^^^^^^^^^^^^^^^^^^^
  File "/home/tnqn/Documents/rentsafe_project/apps/leases/api/serializers.py", line 330, in create
    raise serializers.ValidationError(f"Address creation failed: {str(e)}")
rest_framework.exceptions.ValidationError: [ErrorDetail(string="Address creation failed: Field 'id' expected a number but got 'US'.", code='invalid')]
ERROR 2025-07-23 13:00:36 views 140547 125462370055872 Lease creation failed: [ErrorDetail(string='Address creation failed: {\'province\': [\'Province "Harare" does not belong to country "Malawi"\']}', code='invalid')]
Traceback (most recent call last):
  File "/home/tnqn/Documents/rentsafe_project/apps/leases/api/serializers.py", line 318, in create
    Address.objects.create(
  File "/home/tnqn/Documents/rentsafe_project/env/lib/python3.12/site-packages/django/db/models/manager.py", line 87, in manager_method
    return getattr(self.get_queryset(), name)(*args, **kwargs)
           ^^^^^^^^^^^^^^^^^^^^^^^^^^^^^^^^^^^^^^^^^^^^^^^^^^^
  File "/home/tnqn/Documents/rentsafe_project/env/lib/python3.12/site-packages/django/db/models/query.py", line 658, in create
    obj.save(force_insert=True, using=self.db)
  File "/home/tnqn/Documents/rentsafe_project/apps/common/models/models.py", line 257, in save
    self.full_clean()
  File "/home/tnqn/Documents/rentsafe_project/env/lib/python3.12/site-packages/django/db/models/base.py", line 1502, in full_clean
    raise ValidationError(errors)
django.core.exceptions.ValidationError: {'province': ['Province "Harare" does not belong to country "Malawi"']}

During handling of the above exception, another exception occurred:

Traceback (most recent call last):
  File "/home/tnqn/Documents/rentsafe_project/apps/leases/api/views.py", line 51, in create
    lease = serializer.save()
            ^^^^^^^^^^^^^^^^^
  File "/home/tnqn/Documents/rentsafe_project/env/lib/python3.12/site-packages/rest_framework/serializers.py", line 212, in save
    self.instance = self.create(validated_data)
                    ^^^^^^^^^^^^^^^^^^^^^^^^^^^
  File "/usr/lib/python3.12/contextlib.py", line 81, in inner
    return func(*args, **kwds)
           ^^^^^^^^^^^^^^^^^^^
  File "/home/tnqn/Documents/rentsafe_project/apps/leases/api/serializers.py", line 401, in create
    property = property_serializer.save()
               ^^^^^^^^^^^^^^^^^^^^^^^^^^
  File "/home/tnqn/Documents/rentsafe_project/env/lib/python3.12/site-packages/rest_framework/serializers.py", line 212, in save
    self.instance = self.create(validated_data)
                    ^^^^^^^^^^^^^^^^^^^^^^^^^^^
  File "/home/tnqn/Documents/rentsafe_project/apps/leases/api/serializers.py", line 330, in create
    raise serializers.ValidationError(f"Address creation failed: {str(e)}")
rest_framework.exceptions.ValidationError: [ErrorDetail(string='Address creation failed: {\'province\': [\'Province "Harare" does not belong to country "Malawi"\']}', code='invalid')]
ERROR 2025-07-23 13:02:11 views 140547 125462349084352 Lease creation failed: [ErrorDetail(string='Address creation failed: {\'province\': [\'Province "Bulawayo" does not belong to country "Malawi"\']}', code='invalid')]
Traceback (most recent call last):
  File "/home/tnqn/Documents/rentsafe_project/apps/leases/api/serializers.py", line 318, in create
    Address.objects.create(
  File "/home/tnqn/Documents/rentsafe_project/env/lib/python3.12/site-packages/django/db/models/manager.py", line 87, in manager_method
    return getattr(self.get_queryset(), name)(*args, **kwargs)
           ^^^^^^^^^^^^^^^^^^^^^^^^^^^^^^^^^^^^^^^^^^^^^^^^^^^
  File "/home/tnqn/Documents/rentsafe_project/env/lib/python3.12/site-packages/django/db/models/query.py", line 658, in create
    obj.save(force_insert=True, using=self.db)
  File "/home/tnqn/Documents/rentsafe_project/apps/common/models/models.py", line 257, in save
    self.full_clean()
  File "/home/tnqn/Documents/rentsafe_project/env/lib/python3.12/site-packages/django/db/models/base.py", line 1502, in full_clean
    raise ValidationError(errors)
django.core.exceptions.ValidationError: {'province': ['Province "Bulawayo" does not belong to country "Malawi"']}

During handling of the above exception, another exception occurred:

Traceback (most recent call last):
  File "/home/tnqn/Documents/rentsafe_project/apps/leases/api/views.py", line 51, in create
    lease = serializer.save()
            ^^^^^^^^^^^^^^^^^
  File "/home/tnqn/Documents/rentsafe_project/env/lib/python3.12/site-packages/rest_framework/serializers.py", line 212, in save
    self.instance = self.create(validated_data)
                    ^^^^^^^^^^^^^^^^^^^^^^^^^^^
  File "/usr/lib/python3.12/contextlib.py", line 81, in inner
    return func(*args, **kwds)
           ^^^^^^^^^^^^^^^^^^^
  File "/home/tnqn/Documents/rentsafe_project/apps/leases/api/serializers.py", line 401, in create
    property = property_serializer.save()
               ^^^^^^^^^^^^^^^^^^^^^^^^^^
  File "/home/tnqn/Documents/rentsafe_project/env/lib/python3.12/site-packages/rest_framework/serializers.py", line 212, in save
    self.instance = self.create(validated_data)
                    ^^^^^^^^^^^^^^^^^^^^^^^^^^^
  File "/home/tnqn/Documents/rentsafe_project/apps/leases/api/serializers.py", line 330, in create
    raise serializers.ValidationError(f"Address creation failed: {str(e)}")
rest_framework.exceptions.ValidationError: [ErrorDetail(string='Address creation failed: {\'province\': [\'Province "Bulawayo" does not belong to country "Malawi"\']}', code='invalid')]
ERROR 2025-07-23 13:03:10 views 140547 125462349084352 Lease creation failed: [ErrorDetail(string='Address creation failed: {\'suburb\': [\'Suburb "Ruwa" does not belong to city "Bulawayo"\']}', code='invalid')]
Traceback (most recent call last):
  File "/home/tnqn/Documents/rentsafe_project/apps/leases/api/serializers.py", line 318, in create
    Address.objects.create(
  File "/home/tnqn/Documents/rentsafe_project/env/lib/python3.12/site-packages/django/db/models/manager.py", line 87, in manager_method
    return getattr(self.get_queryset(), name)(*args, **kwargs)
           ^^^^^^^^^^^^^^^^^^^^^^^^^^^^^^^^^^^^^^^^^^^^^^^^^^^
  File "/home/tnqn/Documents/rentsafe_project/env/lib/python3.12/site-packages/django/db/models/query.py", line 658, in create
    obj.save(force_insert=True, using=self.db)
  File "/home/tnqn/Documents/rentsafe_project/apps/common/models/models.py", line 257, in save
    self.full_clean()
  File "/home/tnqn/Documents/rentsafe_project/env/lib/python3.12/site-packages/django/db/models/base.py", line 1502, in full_clean
    raise ValidationError(errors)
django.core.exceptions.ValidationError: {'suburb': ['Suburb "Ruwa" does not belong to city "Bulawayo"']}

During handling of the above exception, another exception occurred:

Traceback (most recent call last):
  File "/home/tnqn/Documents/rentsafe_project/apps/leases/api/views.py", line 51, in create
    lease = serializer.save()
            ^^^^^^^^^^^^^^^^^
  File "/home/tnqn/Documents/rentsafe_project/env/lib/python3.12/site-packages/rest_framework/serializers.py", line 212, in save
    self.instance = self.create(validated_data)
                    ^^^^^^^^^^^^^^^^^^^^^^^^^^^
  File "/usr/lib/python3.12/contextlib.py", line 81, in inner
    return func(*args, **kwds)
           ^^^^^^^^^^^^^^^^^^^
  File "/home/tnqn/Documents/rentsafe_project/apps/leases/api/serializers.py", line 401, in create
    property = property_serializer.save()
               ^^^^^^^^^^^^^^^^^^^^^^^^^^
  File "/home/tnqn/Documents/rentsafe_project/env/lib/python3.12/site-packages/rest_framework/serializers.py", line 212, in save
    self.instance = self.create(validated_data)
                    ^^^^^^^^^^^^^^^^^^^^^^^^^^^
  File "/home/tnqn/Documents/rentsafe_project/apps/leases/api/serializers.py", line 330, in create
    raise serializers.ValidationError(f"Address creation failed: {str(e)}")
rest_framework.exceptions.ValidationError: [ErrorDetail(string='Address creation failed: {\'suburb\': [\'Suburb "Ruwa" does not belong to city "Bulawayo"\']}', code='invalid')]
ERROR 2025-07-23 13:03:48 views 142314 139872645936832 Lease creation failed: [ErrorDetail(string='Address creation failed: Error -3 connecting to redis:6379. Temporary failure in name resolution.', code='invalid')]
Traceback (most recent call last):
  File "/home/tnqn/Documents/rentsafe_project/env/lib/python3.12/site-packages/django_redis/cache.py", line 29, in _decorator
    return method(self, *args, **kwargs)
           ^^^^^^^^^^^^^^^^^^^^^^^^^^^^^
  File "/home/tnqn/Documents/rentsafe_project/env/lib/python3.12/site-packages/django_redis/cache.py", line 81, in set
    return self.client.set(*args, **kwargs)
           ^^^^^^^^^^^^^^^^^^^^^^^^^^^^^^^^
  File "/home/tnqn/Documents/rentsafe_project/env/lib/python3.12/site-packages/django_redis/client/default.py", line 224, in set
    raise ConnectionInterrupted(connection=client) from e
django_redis.exceptions.ConnectionInterrupted: Redis ConnectionError: Error -3 connecting to redis:6379. Temporary failure in name resolution.

During handling of the above exception, another exception occurred:

Traceback (most recent call last):
  File "/home/tnqn/Documents/rentsafe_project/apps/leases/api/serializers.py", line 318, in create
    Address.objects.create(
  File "/home/tnqn/Documents/rentsafe_project/env/lib/python3.12/site-packages/django/db/models/manager.py", line 87, in manager_method
    return getattr(self.get_queryset(), name)(*args, **kwargs)
           ^^^^^^^^^^^^^^^^^^^^^^^^^^^^^^^^^^^^^^^^^^^^^^^^^^^
  File "/home/tnqn/Documents/rentsafe_project/env/lib/python3.12/site-packages/django/db/models/query.py", line 658, in create
    obj.save(force_insert=True, using=self.db)
  File "/home/tnqn/Documents/rentsafe_project/apps/common/models/models.py", line 270, in save
    super().save(*args, **kwargs)
  File "/home/tnqn/Documents/rentsafe_project/apps/common/models/base_models.py", line 29, in save
    super().save(*args, **kwargs)
  File "/home/tnqn/Documents/rentsafe_project/env/lib/python3.12/site-packages/django/db/models/base.py", line 814, in save
    self.save_base(
  File "/home/tnqn/Documents/rentsafe_project/env/lib/python3.12/site-packages/django/db/models/base.py", line 892, in save_base
    post_save.send(
  File "/home/tnqn/Documents/rentsafe_project/env/lib/python3.12/site-packages/django/dispatch/dispatcher.py", line 177, in send
    (receiver, receiver(signal=self, sender=sender, **named))
               ^^^^^^^^^^^^^^^^^^^^^^^^^^^^^^^^^^^^^^^^^^^^^
  File "/home/tnqn/Documents/rentsafe_project/apps/common/utils/signals.py", line 114, in invalidate_model_cache
    CacheService.invalidate_tag('*')
  File "/home/tnqn/Documents/rentsafe_project/apps/common/utils/caching.py", line 51, in invalidate_tag
    cache.set(version_key, new_version, cls.VERSION_TIMEOUT)
  File "/home/tnqn/Documents/rentsafe_project/env/lib/python3.12/site-packages/django_redis/cache.py", line 36, in _decorator
    raise e.__cause__  # noqa: B904
    ^^^^^^^^^^^^^^^^^
  File "/home/tnqn/Documents/rentsafe_project/env/lib/python3.12/site-packages/django_redis/client/default.py", line 214, in set
    return bool(client.set(nkey, nvalue, nx=nx, px=timeout, xx=xx))
                ^^^^^^^^^^^^^^^^^^^^^^^^^^^^^^^^^^^^^^^^^^^^^^^^^^
  File "/home/tnqn/Documents/rentsafe_project/env/lib/python3.12/site-packages/redis/commands/core.py", line 2341, in set
    return self.execute_command("SET", *pieces, **options)
           ^^^^^^^^^^^^^^^^^^^^^^^^^^^^^^^^^^^^^^^^^^^^^^^
  File "/home/tnqn/Documents/rentsafe_project/env/lib/python3.12/site-packages/redis/client.py", line 533, in execute_command
    conn = self.connection or pool.get_connection(command_name, **options)
                              ^^^^^^^^^^^^^^^^^^^^^^^^^^^^^^^^^^^^^^^^^^^^
  File "/home/tnqn/Documents/rentsafe_project/env/lib/python3.12/site-packages/redis/connection.py", line 1086, in get_connection
    connection.connect()
  File "/home/tnqn/Documents/rentsafe_project/env/lib/python3.12/site-packages/redis/connection.py", line 270, in connect
    raise ConnectionError(self._error_message(e))
redis.exceptions.ConnectionError: Error -3 connecting to redis:6379. Temporary failure in name resolution.

During handling of the above exception, another exception occurred:

Traceback (most recent call last):
  File "/home/tnqn/Documents/rentsafe_project/apps/leases/api/views.py", line 51, in create
    lease = serializer.save()
            ^^^^^^^^^^^^^^^^^
  File "/home/tnqn/Documents/rentsafe_project/env/lib/python3.12/site-packages/rest_framework/serializers.py", line 212, in save
    self.instance = self.create(validated_data)
                    ^^^^^^^^^^^^^^^^^^^^^^^^^^^
  File "/usr/lib/python3.12/contextlib.py", line 81, in inner
    return func(*args, **kwds)
           ^^^^^^^^^^^^^^^^^^^
  File "/home/tnqn/Documents/rentsafe_project/apps/leases/api/serializers.py", line 401, in create
    property = property_serializer.save()
               ^^^^^^^^^^^^^^^^^^^^^^^^^^
  File "/home/tnqn/Documents/rentsafe_project/env/lib/python3.12/site-packages/rest_framework/serializers.py", line 212, in save
    self.instance = self.create(validated_data)
                    ^^^^^^^^^^^^^^^^^^^^^^^^^^^
  File "/home/tnqn/Documents/rentsafe_project/apps/leases/api/serializers.py", line 330, in create
    raise serializers.ValidationError(f"Address creation failed: {str(e)}")
rest_framework.exceptions.ValidationError: [ErrorDetail(string='Address creation failed: Error -3 connecting to redis:6379. Temporary failure in name resolution.', code='invalid')]
ERROR 2025-07-23 13:29:04 views 152477 124397956363968 Lease creation failed: [ErrorDetail(string='Address creation failed: Error -3 connecting to redis:6379. Temporary failure in name resolution.', code='invalid')]
Traceback (most recent call last):
  File "/home/tnqn/Documents/rentsafe_project/env/lib/python3.12/site-packages/django_redis/cache.py", line 29, in _decorator
    return method(self, *args, **kwargs)
           ^^^^^^^^^^^^^^^^^^^^^^^^^^^^^
  File "/home/tnqn/Documents/rentsafe_project/env/lib/python3.12/site-packages/django_redis/cache.py", line 81, in set
    return self.client.set(*args, **kwargs)
           ^^^^^^^^^^^^^^^^^^^^^^^^^^^^^^^^
  File "/home/tnqn/Documents/rentsafe_project/env/lib/python3.12/site-packages/django_redis/client/default.py", line 224, in set
    raise ConnectionInterrupted(connection=client) from e
django_redis.exceptions.ConnectionInterrupted: Redis ConnectionError: Error -3 connecting to redis:6379. Temporary failure in name resolution.

During handling of the above exception, another exception occurred:

Traceback (most recent call last):
  File "/home/tnqn/Documents/rentsafe_project/apps/leases/api/serializers.py", line 318, in create
    Address.objects.create(
  File "/home/tnqn/Documents/rentsafe_project/env/lib/python3.12/site-packages/django/db/models/manager.py", line 87, in manager_method
    return getattr(self.get_queryset(), name)(*args, **kwargs)
           ^^^^^^^^^^^^^^^^^^^^^^^^^^^^^^^^^^^^^^^^^^^^^^^^^^^
  File "/home/tnqn/Documents/rentsafe_project/env/lib/python3.12/site-packages/django/db/models/query.py", line 658, in create
    obj.save(force_insert=True, using=self.db)
  File "/home/tnqn/Documents/rentsafe_project/apps/common/models/models.py", line 270, in save
    super().save(*args, **kwargs)
  File "/home/tnqn/Documents/rentsafe_project/apps/common/models/base_models.py", line 29, in save
    super().save(*args, **kwargs)
  File "/home/tnqn/Documents/rentsafe_project/env/lib/python3.12/site-packages/django/db/models/base.py", line 814, in save
    self.save_base(
  File "/home/tnqn/Documents/rentsafe_project/env/lib/python3.12/site-packages/django/db/models/base.py", line 892, in save_base
    post_save.send(
  File "/home/tnqn/Documents/rentsafe_project/env/lib/python3.12/site-packages/django/dispatch/dispatcher.py", line 177, in send
    (receiver, receiver(signal=self, sender=sender, **named))
               ^^^^^^^^^^^^^^^^^^^^^^^^^^^^^^^^^^^^^^^^^^^^^
  File "/home/tnqn/Documents/rentsafe_project/apps/common/utils/signals.py", line 114, in invalidate_model_cache
    CacheService.invalidate_tag('*')
  File "/home/tnqn/Documents/rentsafe_project/apps/common/utils/caching.py", line 51, in invalidate_tag
    cache.set(version_key, new_version, cls.VERSION_TIMEOUT)
  File "/home/tnqn/Documents/rentsafe_project/env/lib/python3.12/site-packages/django_redis/cache.py", line 36, in _decorator
    raise e.__cause__  # noqa: B904
    ^^^^^^^^^^^^^^^^^
  File "/home/tnqn/Documents/rentsafe_project/env/lib/python3.12/site-packages/django_redis/client/default.py", line 214, in set
    return bool(client.set(nkey, nvalue, nx=nx, px=timeout, xx=xx))
                ^^^^^^^^^^^^^^^^^^^^^^^^^^^^^^^^^^^^^^^^^^^^^^^^^^
  File "/home/tnqn/Documents/rentsafe_project/env/lib/python3.12/site-packages/redis/commands/core.py", line 2341, in set
    return self.execute_command("SET", *pieces, **options)
           ^^^^^^^^^^^^^^^^^^^^^^^^^^^^^^^^^^^^^^^^^^^^^^^
  File "/home/tnqn/Documents/rentsafe_project/env/lib/python3.12/site-packages/redis/client.py", line 533, in execute_command
    conn = self.connection or pool.get_connection(command_name, **options)
                              ^^^^^^^^^^^^^^^^^^^^^^^^^^^^^^^^^^^^^^^^^^^^
  File "/home/tnqn/Documents/rentsafe_project/env/lib/python3.12/site-packages/redis/connection.py", line 1086, in get_connection
    connection.connect()
  File "/home/tnqn/Documents/rentsafe_project/env/lib/python3.12/site-packages/redis/connection.py", line 270, in connect
    raise ConnectionError(self._error_message(e))
redis.exceptions.ConnectionError: Error -3 connecting to redis:6379. Temporary failure in name resolution.

During handling of the above exception, another exception occurred:

Traceback (most recent call last):
  File "/home/tnqn/Documents/rentsafe_project/apps/leases/api/views.py", line 51, in create
    lease = serializer.save()
            ^^^^^^^^^^^^^^^^^
  File "/home/tnqn/Documents/rentsafe_project/env/lib/python3.12/site-packages/rest_framework/serializers.py", line 212, in save
    self.instance = self.create(validated_data)
                    ^^^^^^^^^^^^^^^^^^^^^^^^^^^
  File "/usr/lib/python3.12/contextlib.py", line 81, in inner
    return func(*args, **kwds)
           ^^^^^^^^^^^^^^^^^^^
  File "/home/tnqn/Documents/rentsafe_project/apps/leases/api/serializers.py", line 397, in create
    property = property_serializer.save()
               ^^^^^^^^^^^^^^^^^^^^^^^^^^
  File "/home/tnqn/Documents/rentsafe_project/env/lib/python3.12/site-packages/rest_framework/serializers.py", line 212, in save
    self.instance = self.create(validated_data)
                    ^^^^^^^^^^^^^^^^^^^^^^^^^^^
  File "/home/tnqn/Documents/rentsafe_project/apps/leases/api/serializers.py", line 330, in create
    raise serializers.ValidationError(f"Address creation failed: {str(e)}")
rest_framework.exceptions.ValidationError: [ErrorDetail(string='Address creation failed: Error -3 connecting to redis:6379. Temporary failure in name resolution.', code='invalid')]
ERROR 2025-07-23 13:30:00 views 153683 131636812314304 Lease creation failed: [ErrorDetail(string='Address creation failed: Error -3 connecting to redis:6379. Temporary failure in name resolution.', code='invalid')]
Traceback (most recent call last):
  File "/home/tnqn/Documents/rentsafe_project/env/lib/python3.12/site-packages/django_redis/cache.py", line 29, in _decorator
    return method(self, *args, **kwargs)
           ^^^^^^^^^^^^^^^^^^^^^^^^^^^^^
  File "/home/tnqn/Documents/rentsafe_project/env/lib/python3.12/site-packages/django_redis/cache.py", line 81, in set
    return self.client.set(*args, **kwargs)
           ^^^^^^^^^^^^^^^^^^^^^^^^^^^^^^^^
  File "/home/tnqn/Documents/rentsafe_project/env/lib/python3.12/site-packages/django_redis/client/default.py", line 224, in set
    raise ConnectionInterrupted(connection=client) from e
django_redis.exceptions.ConnectionInterrupted: Redis ConnectionError: Error -3 connecting to redis:6379. Temporary failure in name resolution.

During handling of the above exception, another exception occurred:

Traceback (most recent call last):
  File "/home/tnqn/Documents/rentsafe_project/apps/leases/api/serializers.py", line 318, in create
    Address.objects.create(
  File "/home/tnqn/Documents/rentsafe_project/env/lib/python3.12/site-packages/django/db/models/manager.py", line 87, in manager_method
    return getattr(self.get_queryset(), name)(*args, **kwargs)
           ^^^^^^^^^^^^^^^^^^^^^^^^^^^^^^^^^^^^^^^^^^^^^^^^^^^
  File "/home/tnqn/Documents/rentsafe_project/env/lib/python3.12/site-packages/django/db/models/query.py", line 658, in create
    obj.save(force_insert=True, using=self.db)
  File "/home/tnqn/Documents/rentsafe_project/apps/common/models/models.py", line 270, in save
    super().save(*args, **kwargs)
  File "/home/tnqn/Documents/rentsafe_project/apps/common/models/base_models.py", line 29, in save
    super().save(*args, **kwargs)
  File "/home/tnqn/Documents/rentsafe_project/env/lib/python3.12/site-packages/django/db/models/base.py", line 814, in save
    self.save_base(
  File "/home/tnqn/Documents/rentsafe_project/env/lib/python3.12/site-packages/django/db/models/base.py", line 892, in save_base
    post_save.send(
  File "/home/tnqn/Documents/rentsafe_project/env/lib/python3.12/site-packages/django/dispatch/dispatcher.py", line 177, in send
    (receiver, receiver(signal=self, sender=sender, **named))
               ^^^^^^^^^^^^^^^^^^^^^^^^^^^^^^^^^^^^^^^^^^^^^
  File "/home/tnqn/Documents/rentsafe_project/apps/common/utils/signals.py", line 114, in invalidate_model_cache
    CacheService.invalidate_tag('*')
  File "/home/tnqn/Documents/rentsafe_project/apps/common/utils/caching.py", line 51, in invalidate_tag
    cache.set(version_key, new_version, cls.VERSION_TIMEOUT)
  File "/home/tnqn/Documents/rentsafe_project/env/lib/python3.12/site-packages/django_redis/cache.py", line 36, in _decorator
    raise e.__cause__  # noqa: B904
    ^^^^^^^^^^^^^^^^^
  File "/home/tnqn/Documents/rentsafe_project/env/lib/python3.12/site-packages/django_redis/client/default.py", line 214, in set
    return bool(client.set(nkey, nvalue, nx=nx, px=timeout, xx=xx))
                ^^^^^^^^^^^^^^^^^^^^^^^^^^^^^^^^^^^^^^^^^^^^^^^^^^
  File "/home/tnqn/Documents/rentsafe_project/env/lib/python3.12/site-packages/redis/commands/core.py", line 2341, in set
    return self.execute_command("SET", *pieces, **options)
           ^^^^^^^^^^^^^^^^^^^^^^^^^^^^^^^^^^^^^^^^^^^^^^^
  File "/home/tnqn/Documents/rentsafe_project/env/lib/python3.12/site-packages/redis/client.py", line 533, in execute_command
    conn = self.connection or pool.get_connection(command_name, **options)
                              ^^^^^^^^^^^^^^^^^^^^^^^^^^^^^^^^^^^^^^^^^^^^
  File "/home/tnqn/Documents/rentsafe_project/env/lib/python3.12/site-packages/redis/connection.py", line 1086, in get_connection
    connection.connect()
  File "/home/tnqn/Documents/rentsafe_project/env/lib/python3.12/site-packages/redis/connection.py", line 270, in connect
    raise ConnectionError(self._error_message(e))
redis.exceptions.ConnectionError: Error -3 connecting to redis:6379. Temporary failure in name resolution.

During handling of the above exception, another exception occurred:

Traceback (most recent call last):
  File "/home/tnqn/Documents/rentsafe_project/apps/leases/api/views.py", line 51, in create
    lease = serializer.save()
            ^^^^^^^^^^^^^^^^^
  File "/home/tnqn/Documents/rentsafe_project/env/lib/python3.12/site-packages/rest_framework/serializers.py", line 212, in save
    self.instance = self.create(validated_data)
                    ^^^^^^^^^^^^^^^^^^^^^^^^^^^
  File "/usr/lib/python3.12/contextlib.py", line 81, in inner
    return func(*args, **kwds)
           ^^^^^^^^^^^^^^^^^^^
  File "/home/tnqn/Documents/rentsafe_project/apps/leases/api/serializers.py", line 397, in create
    property = property_serializer.save()
               ^^^^^^^^^^^^^^^^^^^^^^^^^^
  File "/home/tnqn/Documents/rentsafe_project/env/lib/python3.12/site-packages/rest_framework/serializers.py", line 212, in save
    self.instance = self.create(validated_data)
                    ^^^^^^^^^^^^^^^^^^^^^^^^^^^
  File "/home/tnqn/Documents/rentsafe_project/apps/leases/api/serializers.py", line 330, in create
    raise serializers.ValidationError(f"Address creation failed: {str(e)}")
rest_framework.exceptions.ValidationError: [ErrorDetail(string='Address creation failed: Error -3 connecting to redis:6379. Temporary failure in name resolution.', code='invalid')]
ERROR 2025-07-23 13:34:08 views 155183 133216866399936 Lease creation failed: [ErrorDetail(string='Address creation failed: Error -3 connecting to redis:6379. Temporary failure in name resolution.', code='invalid')]
Traceback (most recent call last):
  File "/home/tnqn/Documents/rentsafe_project/env/lib/python3.12/site-packages/django_redis/cache.py", line 29, in _decorator
    return method(self, *args, **kwargs)
           ^^^^^^^^^^^^^^^^^^^^^^^^^^^^^
  File "/home/tnqn/Documents/rentsafe_project/env/lib/python3.12/site-packages/django_redis/cache.py", line 81, in set
    return self.client.set(*args, **kwargs)
           ^^^^^^^^^^^^^^^^^^^^^^^^^^^^^^^^
  File "/home/tnqn/Documents/rentsafe_project/env/lib/python3.12/site-packages/django_redis/client/default.py", line 224, in set
    raise ConnectionInterrupted(connection=client) from e
django_redis.exceptions.ConnectionInterrupted: Redis ConnectionError: Error -3 connecting to redis:6379. Temporary failure in name resolution.

During handling of the above exception, another exception occurred:

Traceback (most recent call last):
  File "/home/tnqn/Documents/rentsafe_project/apps/leases/api/serializers.py", line 318, in create
    Address.objects.create(
  File "/home/tnqn/Documents/rentsafe_project/env/lib/python3.12/site-packages/django/db/models/manager.py", line 87, in manager_method
    return getattr(self.get_queryset(), name)(*args, **kwargs)
           ^^^^^^^^^^^^^^^^^^^^^^^^^^^^^^^^^^^^^^^^^^^^^^^^^^^
  File "/home/tnqn/Documents/rentsafe_project/env/lib/python3.12/site-packages/django/db/models/query.py", line 658, in create
    obj.save(force_insert=True, using=self.db)
  File "/home/tnqn/Documents/rentsafe_project/apps/common/models/models.py", line 270, in save
    super().save(*args, **kwargs)
  File "/home/tnqn/Documents/rentsafe_project/apps/common/models/base_models.py", line 29, in save
    super().save(*args, **kwargs)
  File "/home/tnqn/Documents/rentsafe_project/env/lib/python3.12/site-packages/django/db/models/base.py", line 814, in save
    self.save_base(
  File "/home/tnqn/Documents/rentsafe_project/env/lib/python3.12/site-packages/django/db/models/base.py", line 892, in save_base
    post_save.send(
  File "/home/tnqn/Documents/rentsafe_project/env/lib/python3.12/site-packages/django/dispatch/dispatcher.py", line 177, in send
    (receiver, receiver(signal=self, sender=sender, **named))
               ^^^^^^^^^^^^^^^^^^^^^^^^^^^^^^^^^^^^^^^^^^^^^
  File "/home/tnqn/Documents/rentsafe_project/apps/common/utils/signals.py", line 114, in invalidate_model_cache
    CacheService.invalidate_tag('*')
  File "/home/tnqn/Documents/rentsafe_project/apps/common/utils/caching.py", line 51, in invalidate_tag
    cache.set(version_key, new_version, cls.VERSION_TIMEOUT)
  File "/home/tnqn/Documents/rentsafe_project/env/lib/python3.12/site-packages/django_redis/cache.py", line 36, in _decorator
    raise e.__cause__  # noqa: B904
    ^^^^^^^^^^^^^^^^^
  File "/home/tnqn/Documents/rentsafe_project/env/lib/python3.12/site-packages/django_redis/client/default.py", line 214, in set
    return bool(client.set(nkey, nvalue, nx=nx, px=timeout, xx=xx))
                ^^^^^^^^^^^^^^^^^^^^^^^^^^^^^^^^^^^^^^^^^^^^^^^^^^
  File "/home/tnqn/Documents/rentsafe_project/env/lib/python3.12/site-packages/redis/commands/core.py", line 2341, in set
    return self.execute_command("SET", *pieces, **options)
           ^^^^^^^^^^^^^^^^^^^^^^^^^^^^^^^^^^^^^^^^^^^^^^^
  File "/home/tnqn/Documents/rentsafe_project/env/lib/python3.12/site-packages/redis/client.py", line 533, in execute_command
    conn = self.connection or pool.get_connection(command_name, **options)
                              ^^^^^^^^^^^^^^^^^^^^^^^^^^^^^^^^^^^^^^^^^^^^
  File "/home/tnqn/Documents/rentsafe_project/env/lib/python3.12/site-packages/redis/connection.py", line 1086, in get_connection
    connection.connect()
  File "/home/tnqn/Documents/rentsafe_project/env/lib/python3.12/site-packages/redis/connection.py", line 270, in connect
    raise ConnectionError(self._error_message(e))
redis.exceptions.ConnectionError: Error -3 connecting to redis:6379. Temporary failure in name resolution.

During handling of the above exception, another exception occurred:

Traceback (most recent call last):
  File "/home/tnqn/Documents/rentsafe_project/apps/leases/api/views.py", line 51, in create
    lease = serializer.save()
            ^^^^^^^^^^^^^^^^^
  File "/home/tnqn/Documents/rentsafe_project/env/lib/python3.12/site-packages/rest_framework/serializers.py", line 212, in save
    self.instance = self.create(validated_data)
                    ^^^^^^^^^^^^^^^^^^^^^^^^^^^
  File "/usr/lib/python3.12/contextlib.py", line 81, in inner
    return func(*args, **kwds)
           ^^^^^^^^^^^^^^^^^^^
  File "/home/tnqn/Documents/rentsafe_project/apps/leases/api/serializers.py", line 397, in create
    property = property_serializer.save()
               ^^^^^^^^^^^^^^^^^^^^^^^^^^
  File "/home/tnqn/Documents/rentsafe_project/env/lib/python3.12/site-packages/rest_framework/serializers.py", line 212, in save
    self.instance = self.create(validated_data)
                    ^^^^^^^^^^^^^^^^^^^^^^^^^^^
  File "/home/tnqn/Documents/rentsafe_project/apps/leases/api/serializers.py", line 330, in create
    raise serializers.ValidationError(f"Address creation failed: {str(e)}")
rest_framework.exceptions.ValidationError: [ErrorDetail(string='Address creation failed: Error -3 connecting to redis:6379. Temporary failure in name resolution.', code='invalid')]
ERROR 2025-07-23 13:35:06 views 155582 135557710608064 Lease creation failed: [ErrorDetail(string='Address creation failed: Error -3 connecting to redis:6379. Temporary failure in name resolution.', code='invalid')]
Traceback (most recent call last):
  File "/home/tnqn/Documents/rentsafe_project/env/lib/python3.12/site-packages/django_redis/cache.py", line 29, in _decorator
    return method(self, *args, **kwargs)
           ^^^^^^^^^^^^^^^^^^^^^^^^^^^^^
  File "/home/tnqn/Documents/rentsafe_project/env/lib/python3.12/site-packages/django_redis/cache.py", line 81, in set
    return self.client.set(*args, **kwargs)
           ^^^^^^^^^^^^^^^^^^^^^^^^^^^^^^^^
  File "/home/tnqn/Documents/rentsafe_project/env/lib/python3.12/site-packages/django_redis/client/default.py", line 224, in set
    raise ConnectionInterrupted(connection=client) from e
django_redis.exceptions.ConnectionInterrupted: Redis ConnectionError: Error -3 connecting to redis:6379. Temporary failure in name resolution.

During handling of the above exception, another exception occurred:

Traceback (most recent call last):
  File "/home/tnqn/Documents/rentsafe_project/apps/leases/api/serializers.py", line 318, in create
    Address.objects.create(
  File "/home/tnqn/Documents/rentsafe_project/env/lib/python3.12/site-packages/django/db/models/manager.py", line 87, in manager_method
    return getattr(self.get_queryset(), name)(*args, **kwargs)
           ^^^^^^^^^^^^^^^^^^^^^^^^^^^^^^^^^^^^^^^^^^^^^^^^^^^
  File "/home/tnqn/Documents/rentsafe_project/env/lib/python3.12/site-packages/django/db/models/query.py", line 658, in create
    obj.save(force_insert=True, using=self.db)
  File "/home/tnqn/Documents/rentsafe_project/apps/common/models/models.py", line 270, in save
    super().save(*args, **kwargs)
  File "/home/tnqn/Documents/rentsafe_project/apps/common/models/base_models.py", line 29, in save
    super().save(*args, **kwargs)
  File "/home/tnqn/Documents/rentsafe_project/env/lib/python3.12/site-packages/django/db/models/base.py", line 814, in save
    self.save_base(
  File "/home/tnqn/Documents/rentsafe_project/env/lib/python3.12/site-packages/django/db/models/base.py", line 892, in save_base
    post_save.send(
  File "/home/tnqn/Documents/rentsafe_project/env/lib/python3.12/site-packages/django/dispatch/dispatcher.py", line 177, in send
    (receiver, receiver(signal=self, sender=sender, **named))
               ^^^^^^^^^^^^^^^^^^^^^^^^^^^^^^^^^^^^^^^^^^^^^
  File "/home/tnqn/Documents/rentsafe_project/apps/common/utils/signals.py", line 114, in invalidate_model_cache
    CacheService.invalidate_tag('*')
  File "/home/tnqn/Documents/rentsafe_project/apps/common/utils/caching.py", line 51, in invalidate_tag
    cache.set(version_key, new_version, cls.VERSION_TIMEOUT)
  File "/home/tnqn/Documents/rentsafe_project/env/lib/python3.12/site-packages/django_redis/cache.py", line 36, in _decorator
    raise e.__cause__  # noqa: B904
    ^^^^^^^^^^^^^^^^^
  File "/home/tnqn/Documents/rentsafe_project/env/lib/python3.12/site-packages/django_redis/client/default.py", line 214, in set
    return bool(client.set(nkey, nvalue, nx=nx, px=timeout, xx=xx))
                ^^^^^^^^^^^^^^^^^^^^^^^^^^^^^^^^^^^^^^^^^^^^^^^^^^
  File "/home/tnqn/Documents/rentsafe_project/env/lib/python3.12/site-packages/redis/commands/core.py", line 2341, in set
    return self.execute_command("SET", *pieces, **options)
           ^^^^^^^^^^^^^^^^^^^^^^^^^^^^^^^^^^^^^^^^^^^^^^^
  File "/home/tnqn/Documents/rentsafe_project/env/lib/python3.12/site-packages/redis/client.py", line 533, in execute_command
    conn = self.connection or pool.get_connection(command_name, **options)
                              ^^^^^^^^^^^^^^^^^^^^^^^^^^^^^^^^^^^^^^^^^^^^
  File "/home/tnqn/Documents/rentsafe_project/env/lib/python3.12/site-packages/redis/connection.py", line 1086, in get_connection
    connection.connect()
  File "/home/tnqn/Documents/rentsafe_project/env/lib/python3.12/site-packages/redis/connection.py", line 270, in connect
    raise ConnectionError(self._error_message(e))
redis.exceptions.ConnectionError: Error -3 connecting to redis:6379. Temporary failure in name resolution.

During handling of the above exception, another exception occurred:

Traceback (most recent call last):
  File "/home/tnqn/Documents/rentsafe_project/apps/leases/api/views.py", line 51, in create
    lease = serializer.save()
            ^^^^^^^^^^^^^^^^^
  File "/home/tnqn/Documents/rentsafe_project/env/lib/python3.12/site-packages/rest_framework/serializers.py", line 212, in save
    self.instance = self.create(validated_data)
                    ^^^^^^^^^^^^^^^^^^^^^^^^^^^
  File "/usr/lib/python3.12/contextlib.py", line 81, in inner
    return func(*args, **kwds)
           ^^^^^^^^^^^^^^^^^^^
  File "/home/tnqn/Documents/rentsafe_project/apps/leases/api/serializers.py", line 397, in create
    property = property_serializer.save()
               ^^^^^^^^^^^^^^^^^^^^^^^^^^
  File "/home/tnqn/Documents/rentsafe_project/env/lib/python3.12/site-packages/rest_framework/serializers.py", line 212, in save
    self.instance = self.create(validated_data)
                    ^^^^^^^^^^^^^^^^^^^^^^^^^^^
  File "/home/tnqn/Documents/rentsafe_project/apps/leases/api/serializers.py", line 330, in create
    raise serializers.ValidationError(f"Address creation failed: {str(e)}")
rest_framework.exceptions.ValidationError: [ErrorDetail(string='Address creation failed: Error -3 connecting to redis:6379. Temporary failure in name resolution.', code='invalid')]
